---
nav: blog
layout: post
title: "python - 异常处理"
author: "wangchao"
tags:
  - python
  - exception
  - '权限'
  - '验证'
category:
  - 'Programing Teach'
show: true
---

[{{ site.nav.home.name }}]({% link index.md %})/
[{{ site.nav.blog.name }}]({% link blog/index.md %})/
[{{ site.nav.blog.subnav.programing.name }}]({% link blog/programing/index.md %})/
{{ page.title }}

参考:[python3面向对象编程](https://book.douban.com/subject/26468916/)

- [抛出异常](#抛出异常)
- [异常处理](#异常处理)
- [异常层级](#异常层级)
- [异常不是例外](#异常不是例外)
- [验证实例](#验证实例)

<span id="抛出异常"></span>

## 抛出异常

一个异常只是一个对象，并且可以自定义异常。

异常对象都继承自[BaseException内置类](https://docs.python.org/3/library/exceptions.html#BaseException)

当程序流控里处理`异常类`时，异常类会很特殊：**所有应该发生的没有发生，除非当一个异常发生时它应该发生**

常见的异常:

- SyntaxError ： 语法错误异常.
- ZeroDivisionError : 零作为除数异常.
- IndexError : 下标错误异常.
- TypeError : 类型错误异常.
- AttributeError : 属性错误异常.
- KeyError : 键值错误异常.
- NameError : 变量名错误异常.

抛出一个异常： `raise TypeError("Only intergers can be added")`

当一个异常被抛出时，会立即停止程序的执行. 在异常之后的任何应该被执行的代码都没有被执行，除非处理这个异常，否则程序将会伴随着一条错误信息退出.

```python
Python 2.7.13 (default, Dec 18 2016, 07:03:39)
[GCC 4.2.1 Compatible Apple LLVM 8.0.0 (clang-800.0.42.1)] on darwin
Type "help", "copyright", "credits" or "license" for more information.
>>> a
Traceback (most recent call last):
  File "<stdin>", line 1, in <module>

NameError: name 'a' is not defined
```

<span id="异常处理"></span>

## 异常处理

try...except 语句处理.

```python
# 捕获全部的异常
try:
  no_return()
except :
  print("I caught an exception")

# 捕获指定异常
try:
  pass
except ZeroDivisionError:
  return "Silly wabbit, you can't divide by zero!"

# 捕获多个异常 - 方式1
try:
  pass
except (ZeroDivisionError, TypeError):
  return "Enter a number other than zero"

# 捕获多个异常 - 方式2
try:
  pass
except ZeroDivisionError:
  return "Enter a number otehr than zero!"
except TypeError:
  return "Enter a numberical value"
except ValueError:
  print("No, No, No, not 13!")
  raise             # 将该异常再抛出

# 使用`as`关键字语法来把捕获到的异常作为变量来访问.
try:
  pass
except Exception as e:
  print('The exception arguments were,', e.args)

# try...except...else...finally.. 没有发生异常时,以及无论是否有异常都会执行的代码.
try:
  pass
except Exception as e:
  print('caught a exception')
else:
  print('This code called if there is no exception')
finally:
  print('This cleanup code is always called')
```

except 语句的顺序通常是从最具体的到最通用的.

<span id="异常层级"></span>

## 异常层级

大部分的异常都是[Exception](https://docs.python.org/3/library/exceptions.html#Exception)的子类.

但并不是所有的异常都继承自`Exception`类. 实际 Exception 类也继承自 [BaseException](https://docs.python.org/3/library/exceptions.html#BaseException)类.

所有的异常都必须扩展BaseException类或者它的一个子类.

两个关键的异常, [SystemExit](https://docs.python.org/3/library/exceptions.html#SystemExit) 和 [KeyboardInterrupt](https://docs.python.org/3/library/exceptions.html#KeyboardInterrupt) 都是直接从BaseException类继承过来的.而不是从Exception类.

- **SystemExit**： 不管程序是否正常退出，SystemExit异常都会被触发，通常是某个地方调用了sys.exit函数.设计这个异常时为了能允许我们在程序最终退出之前清理代码.但一般不需要显示的处理它.(清理都在finally语句中处理了，对吧？)
- **KeyboardInterrupt**：这个异常通常用于命令行程序,当用户使用以来于操作系统的组合键(Ctrl+C)显式地打断程序执行时，这个异常会被抛出.

具体的层级参考:[Exception hierarchy](https://docs.python.org/3/library/exceptions.html#exception-hierarchy)

使用except: 语句而没有指定任何类型的异常时，它将会捕获所有BaseExcetption的子类,也就是说它将会捕获除了这两个“特殊”异常外的其他异常.

**定义自己的异常**：

从Exception类继承即可，甚至不需要给这个子类添加任何内容.

也可以直接扩展BaseException类，但将不会被通用的`except Exception`语句捕获.

```python
class InvalidWithdrawal(Exception):
    pass

# 使用:
raise InvalidWithdrawal("You don't have $50 in your account")

# 定制初始化函数:
class InvalidWithdrawal(Exception):
    def __init__(self, balance, amount):
        super().__init__("account doesn't have ${}".format(amount))
        self.amount = amount
        self.balance = balance

    def overage(self):
        return self.amount - self.balance

# 如果构造自定义的异常
raise InvalidWithdrawal(25,50)

# 捕获自定义的异常
try:
  raise InvalidWithdrawal(25,50)
except InvalidWithdrawal as e:
  print("I'm sorry, but your withdrdawal is"
        " more than your balance by"
        " ${}".format(e.overage()))
```

定义自己的异常有很多原因：

- 给一个异常信息添加信息或者以某种方式写日志通常是有用的。
- 创建一个其他用户可以访问的框架、库、或者API时，**客户化的异常** 才真正变的有意义.

小心确保所抛出的异常能让客户端程序员看得懂，容易处理，并且很清楚地描述了出了什么问题，这样才能修复和处理它.

<span id="异常不是例外"></span>

## 异常不是例外

简而言之，对于例外的情况要使用异常，即使这些情况都只是一些很小的例外.

例如缺货：抛出 OutOfStockException异常.

注意如何使用 所有可能的 异常处理语句 来 确保 在 正确的时间发生正确的行为.

尽管异常不是一个很可怕的意外情况，可以适当地使用异常来处理它，也可以使用if...elif...else结构来编写，但是那样的代码不容易维护或阅读.

**可以使用异常在不同的方法之间传递信息**,附加在对象上的信息可以很容易地在程序的两个不同部分传递.

使用异常做程序流控可以用于一些方便的程序设计。 异常并不是一个我们需要尽量避免的坏事。 有一个异常发生并不是说，“你应该阻止这种情况的发生”。
相反，它只不过是 两部分可能直接相互调用的代码之间 交互信息 的有力方式.

<span id="验证实例"></span>

**案例学习**

设计一个简单的，集身份验证和授权一体的系统.
整个系统将放到一个模块里，其他代码出于身份验证和授权的目的可以查询这个模块对象.

```python
# 用户类
import hashlib

class User:
    def __init__(self, username, password):
        """Create a new user object . The password
        will be encrypted before stroing."""
        self.username = username
        self.password = self._encrypt_pw(password)
        self.is_logged_in = False

    def _encrypt_pw(self, password):
        """Encrypt the password with the username and
        return the sha digest """
        hash_string = (self.username + password)
        hash_string = hash_string.encode('utf-8')
        return hashlib.sha256(hash_string).hexdigest()

    def check_password(self, password):
        """Return True if the password is valid for this user,
        false otherwise."""
        encrypted = self._encrypt_pw(password)
        return encrypted == self.password

# 验证异常
class AuthException(Exception):
    def __init__(self, username, user=None):
        super().__init__(username, user)
        self.username = username
        self.user = user

class UsernameAlreadyExists(AuthException):
    pass

class PasswordTooShort(AuthException):
    pass

class InvalidUsername(AuthException):
    pass

class InvalidPassword(AuthException):
    pass

# 验证类
class Authenticator:
    def __init__(self):
        """Construct an authenticator to manage
        users logging in and out."""
        self.users = {}

    def add_user(self, username, password):
        if username in self.users:
            raise UsernameAlreadyExists(username)
        if len(password) < 6 :
            raise PasswordTooShort(username)

        self.users[username] = User(username, password)

    def login(self, username, password):
        try:
            user = self.users[username]
        except KeyError:
            raise InvalidUsername(username)

        if not user.check_password(password):
            raise InvalidPassword(username, user)

        user.is_logged_in = True
        return True

    def is_logged_in(self, username):
        if username in self.users:
            return self.users[username].is_logged_in
        return False

# 验证器
class Authorizor:
    def __init__(self, authenticator):
        self.authenticator = authenticator
        self.permissions = {}

    def add_permission(self, perm_name):
        """Create a new permission that users
        can be added to """
        try:
            perm_set = self.permissions[perm_name]
        except KeyError:
            self.permissions[perm_name] = set()  # 使用集合而不是list.
        else :
            raise PermissionError("Permisssion Exists")

    def permit_user(self, perm_name, username):
        """Grant the given permission to the user"""
        try:
            perm_set = self.permissions[perm_name]
        except KeyError:
            raise PermissionError("Permission does not exists")
        else:
            if username not in self.authenticator.users:
                raise InvalidUsername(username)
            perm_set.add(username)

    def check_permission(self, perm_name, username):
        if not self.authenticator.is_logged_in(username):
            raise NotLoggedInError(username)
        try:
            perm_set = self.permissions[perm_name]
        except KeyError:
            raise PermissionError("Permission does not exists")
        else:
            if username not in perm_set :
                raise NotePermittedError(username)
            else:
                return True

# 验证异常
class PermissionError(Exception):
    pass

class NotLoggedInError(AuthException):
    pass

class NotePermittedError(AuthException):
    pass

# 实例化一个默认的验证器
authenticator = Authenticator()
authorizor = Authorizor(authenticator)
```

**测试该认证/授权系统**

```shell
$ /Users/wangchao/workpath python3
Python 3.6.0 (default, Mar  4 2017, 12:32:34)
[GCC 4.2.1 Compatible Apple LLVM 8.0.0 (clang-800.0.42.1)] on darwin
Type "help", "copyright", "credits" or "license" for more information.
>>> import auth
>>> auth.authenticator.add_user("joe","joepassword")      # 添加用户，“joe”

>>> auth.authorizor.add_permission("paint")               # 添加许可组，“paint”
>>> auth.authorizor.check_permission("paint","joe")       # 检查 “joe” 是否拥有 “paint” 权限
Traceback (most recent call last):
 File "<stdin>", line 1, in <module>
 File "/Users/wangchao/workpath/auth.py", line 104, in check_permission
   raise NotLoggedInError(username)
auth.NotLoggedInError: ('joe', None)                      # 该用户没有登录异常
>>> auth.authenticator.is_logged_in("joe")                # 该用户是否登录
False                                                     # 该用户没有登录
>>> auth.authenticator.login("joe","joepassword")         # 登录该用户
True                                                      # 该用户登录成功
>>> auth.authorizor.check_permission("paint","joe")       # 检查用户的“paint”许可.
Traceback (most recent call last):
 File "<stdin>", line 1, in <module>
 File "/Users/wangchao/workpath/auth.py", line 111, in check_permission
   raise NotePermittedError(username)
auth.NotePermittedError: ('joe', None)                    # 没有许可异常,为什么不返回False？客户化异常，并返回相关信息(username), 异常可在不同的地方传递信息.
>>> auth.authorizor.check_permission("mix","joe")         # 检查用户的“mix”许可.
Traceback (most recent call last):
  File "/Users/wangchao/workpath/auth.py", line 106, in check_permission
    perm_set = self.permissions[perm_name]
KeyError: 'mix'                                           # 读取许可时出错

During handling of the above exception, another exception occurred:

Traceback (most recent call last):
  File "<stdin>", line 1, in <module>
  File "/Users/wangchao/workpath/auth.py", line 108, in check_permission
    raise PermissionError("Permission does not exists")
auth.PermissionError: Permission does not exists          # 该许可不存在
>>> auth.authorizor.permit_user("mix","joe")              # 添加用户到不存在的许可.
Traceback (most recent call last):
  File "/Users/wangchao/workpath/auth.py", line 94, in permit_user
    perm_set = self.permissions[perm_name]
KeyError: 'mix'                                           # 读取许可时出错

During handling of the above exception, another exception occurred:

Traceback (most recent call last):
  File "<stdin>", line 1, in <module>
  File "/Users/wangchao/workpath/auth.py", line 96, in permit_user
    raise PermissionError("Permission does not exists")
auth.PermissionError: Permission does not exists          # 该许可不存在
>>> auth.authorizor.permit_user("paint","joe")            # 向用户“joe”添加许可“paint”
>>> auth.authorizor.check_permission("paint","joe")       # 校验用户“joe”是否拥有“paint”许可，
True        # 这儿很关键，如果没有许可，则抛出 客户化 的异常并且携带了用户名信息(username)，
            # 而不是直接返回False, 高明之处. 可传递信息到不同的地方(捕获该异常的地方)
```

该输出显示了所有代码以及绝大多数的异常，但要真正了解所定义的API，还应该写一些异常处理代码并且真正去使用它。

例如：基本的用户菜单接口，运行特定的用户去改变或测试程序。

```python
import auth

# 创建一个测试用户并设置权限
auth.authenticator.add_user("joe","joepassword")
auth.authorizor.add_permission("test program")
auth.authorizor.add_permission("change program")
auth.authorizor.permit_user("test program", "joe")

class Editor:
    """python3 不需要显式继承人object"""

    def __init__(self):
        self.username = None
        self.menu_map = {
            "login":self.login,
            "test":self.test,
            "change":self.change,
            "quit":self.quit
        }

    def login(self):
        logeed_in = False
        while not logeed_in:
            username = input("username:")
            password = input("password:")
            try:
                logeed_in = auth.authenticator.login(username, password)
            except auth.InvalidUsername:
                print("Sorry, that username does not exist")
            except auth.InvalidPassword:
                print("Sorry, incorret password")
            else:
                self.username = username

    def is_permitted(self, permission):
        try:
            auth.authorizor.check_permission(permission, self.username)
        except auth.NotLoggedInError as e:
            print("{} is not logeed in.".format(e.username))    # execption 携带的信息，体现出威力了.
            return False
        except auth.NotePermittedError as e:
            print("{} cannot {}".format(e.username, permission))
            return False
        else:
            return True

    def test(self):
        if self.is_permitted("test program"):
            print("Testing program now...")

    def change(self):
        if self.is_permitted("change program"):
            print("Changing program now...")

    def quit(self):
        raise SystemExit()

    def menu(self):
        try:
            answer = ""
            while True:
                print("Please enter a command:\n"
                      "\tlogin\tLogin\n"
                      "\ttest\tTest program\n"
                      "\tchange\tChange program\n"
                      "\tquit\tQuit\n")
                answer = input("enter a command: ").lower()
                try:
                    func = self.menu_map[answer]
                except KeyError:
                    print("{} is not a valid option".format(answer))
                else:
                    func()
        finally:
            print("Thank you for testing the auth module")

# 默认测试实例
Editor().menu()
```

**测试**

```shell
$ /Users/wangchao/workpath python3 test_auth.py
Please enter a command:
        login   Login
        test    Test program
        change  Change program
        quit    Quit


enter a command: test
None is not logeed in.
Please enter a command:
        login   Login
        test    Test program
        change  Change program
        quit    Quit

enter a command: login
username:joe
password:joes
Sorry, incorret password
username:joes
password:joes
Sorry, that username does not exist
username:joe
password:joepassword
Please enter a command:
        login   Login
        test    Test program
        change  Change program
        quit    Quit

enter a command: test1
test1 is not a valid option
Please enter a command:
        login   Login
        test    Test program
        change  Change program
        quit    Quit

enter a command: test
Testing program now...
Please enter a command:
        login   Login
        test    Test program
        change  Change program
        quit    Quit

        enter a command: change
joe cannot change program
Please enter a command:
        login   Login
        test    Test program
        change  Change program
        quit    Quit

enter a command: quit
Thank you for testing the auth module
```
